<?xml version="1.0"?>
<robot xmlns:sensor="http://playerstage.sourceforge.net/gazebo/xmlschema/#sensor"
       xmlns:controller="http://playerstage.sourceforge.net/gazebo/xmlschema/#controller"
       xmlns:interface="http://playerstage.sourceforge.net/gazebo/xmlschema/#interface"
       xmlns:xacro="http://ros.org/wiki/xacro">
	
<xacro:include filename="$(find aros_description)/urdf/common.xacro" />
	   
<xacro:macro name="aros_arm_v0" params="prefix name parent link revolute lower upper *origin">
    <link name="${prefix}_${name}_link">
	 <visual>
        <geometry>
              <mesh filename="package://aros_description/meshes/arm/link${link}/body.dae" />
        </geometry>
      </visual>
		
	<collision>
      <geometry>
        <mesh filename="package://aros_description/meshes/arm/link${link}/link.dae" />
      </geometry>
    </collision>
    </link>	
	
	<xacro:unless value="${revolute}">
	  <joint name="${parent}_to_${prefix}_${name}" type="fixed">
		<parent link="${parent}_link"/>
		<child link="${prefix}_${name}_link"/>
		<insert_block name="origin" />
	  </joint>
	</xacro:unless>

	<xacro:if value="${revolute}">
	 <joint name="${prefix}_joint${link}" type="revolute">
		<axis xyz="0 0 1"/>
		<limit effort="${EFFORT}" lower="${lower}" upper="${upper}" velocity="${VELOCITY}"/>
		<parent link="${prefix}_${parent}_link"/>
		<child link="${prefix}_${name}_link"/>
		<insert_block name="origin" />
	  </joint>
	</xacro:if>	
</xacro:macro>
	
</robot>