<?xml version="1.0"?>
<robot name="aros">  
  
  <link name="base_link">
    <visual>
      <geometry>
        <mesh filename="package://aros_description/meshes/base/body.dae" />
      </geometry>
       <!-- <origin xyz="4.7 -0.47 0.814" rpy="0 0 0" /> --> 
    </visual>
  </link>
    
   <link name="torso_link">
    <visual>
      <geometry>
        <mesh filename="package://aros_description/meshes/torso/torso.dae" />
      </geometry>
      <!-- <origin xyz="4.7 -0.47 1.203" rpy="0 0 0" /> --> 
    </visual>
  </link>
  
     <link name="pan_body_link">
    <visual>
      <geometry>
        <mesh filename="package://aros_description/meshes/pan_body/pan_body.dae" />
      </geometry>
      <!-- <origin xyz="4.7 -0.475 1.65" rpy="0 0 0" /> --> 
    </visual>
  </link>
  
   <link name="neck_link">
    <visual>
      <geometry>
        <mesh filename="package://aros_description/meshes/neck/neck.dae" />
      </geometry>
      <!-- <origin xyz="4.7 -0.475 1.6944" rpy="0 0 0" /> --> 
    </visual>
  </link>
  
   <link name="vision_link">
    <visual>
      <geometry>
        <mesh filename="package://aros_description/meshes/vision/vision.dae" />
      </geometry>
      <!-- <origin xyz="4.7 -0.475 1.7447" rpy="0 0 0" /> --> 
    </visual>
  </link>
  
  <!-- the right arm -->
  
   <link name="right_arm0_link">
    <visual>
      <geometry>
        <mesh filename="package://aros_description/meshes/right_arm/link0/body.dae" />
      </geometry>
      <!-- <origin xyz="4.7 -0.325 1.5" rpy="0 0 0" /> --> 
    </visual>
  </link> 
  
 
   <link name="right_arm1_link">
    <visual>
      <geometry>
        <mesh filename="package://aros_description/meshes/right_arm/link1/body.dae" />
      </geometry>
      <!-- <origin xyz="4.7 -0.125 1.5" rpy="0 0 0" /> -->  
  </visual>
  </link>

  
  <link name="right_arm2_link">
    <visual>
      <geometry>
        <mesh filename="package://aros_description/meshes/right_arm/link2/body.dae" />
      </geometry> 
      <!-- <origin xyz="4.75 -0.07068 1.454" rpy="0 0 0" /> --> 
   </visual>
  </link> 
  
  <link name="right_arm3_link">
    <visual>
      <geometry>
        <mesh filename="package://aros_description/meshes/right_arm/link3/body.dae" />
      </geometry> 
      <!-- <origin xyz="4.7 0.234 1.51" rpy="0 0 0" /> --> 
   </visual>
  </link> 
  
  <link name="right_arm4_link">
    <visual>
      <geometry>
        <mesh filename="package://aros_description/meshes/right_arm/link4/body.dae" />
      </geometry> 
      <!-- <origin xyz="4.7 0.411 1.5" rpy="0 0 0" /> --> 
   </visual>
  </link> 

   <link name="right_arm5_link">
    <visual>
      <geometry>
        <mesh filename="package://aros_description/meshes/right_arm/link5/body.dae" />
      </geometry> 
      <!-- <origin xyz="4.7 0.6122 1.5" rpy="0 0 0" /> --> 
   </visual>
  </link> 
  
  <link name="right_arm6_link">
    <visual>
      <geometry>
        <mesh filename="package://aros_description/meshes/right_arm/link6/body.dae" />
      </geometry> 
      <!-- <origin xyz="4.7 0.6 1.5" rpy="0 0 0" /> --> 
   </visual>
  </link> 
  
  <link name="right_arm7_link">
    <visual>
      <geometry>
        <mesh filename="package://aros_description/meshes/right_arm/link7/body.dae" />
      </geometry> 
      <!-- <origin xyz="4.7 0.751 1.5" rpy="0 0 0" /> --> 
   </visual>
  </link> 
  
  <link name="right_fts_link">
    <visual>
      <geometry>
        <mesh filename="package://aros_description/meshes/right_arm/fts/body.dae" />
      </geometry> 
      <!-- <origin xyz="4.7 0.751 1.5" rpy="0 0 0" /> --> 
   </visual>
  </link> 
  
  <link name="right_adapter_link">
    <visual>
      <geometry>
        <mesh filename="package://aros_description/meshes/right_arm/adapter/body.dae" />
      </geometry> 
      <!-- <origin xyz="4.7 0.751 1.5" rpy="0 0 0" /> --> 
   </visual>
  </link> 
  
  <link name="right_hand_link">
    <visual>
      <geometry>
        <mesh filename="package://aros_description/meshes/right_arm/barrett_hand/body.dae" />
      </geometry> 
      <!-- <origin xyz="4.7 0.751 1.5" rpy="0 0 0" /> --> 
   </visual>
  </link> 
  
  <link name="right_hand_sensor_link">
    <visual>
      <geometry>
        <mesh filename="package://aros_description/meshes/right_arm/hand_sensor/body.dae" />
      </geometry> 
      <!-- <origin xyz="4.7 0.751 1.5" rpy="0 0 0" /> --> 
   </visual>
  </link>
  
 <!-- finger 1 --> 
  <link name="right_finger1_base_link">
    <visual>
      <geometry>
        <mesh filename="package://aros_description/meshes/right_arm/fingers/finger1/base/body.dae" />
      </geometry> 
      <!-- <origin xyz="4.73 0.933 1.53" rpy="0 0 0" /> --> 
   </visual>
  </link> 
  <!-- finger 2 -->
  
  <!-- finger 3 -->
  
  <link name="right_finger3_1_link">
    <visual>
      <geometry>
        <mesh filename="package://aros_description/meshes/right_arm/fingers/finger3/link1/body.dae" />
      </geometry> 
      <!-- <origin xyz="4.7 0.946 1.42" rpy="0 0 0" /> --> 
   </visual>
  </link> 
  
  <link name="right_finger3_2_link">
    <visual>
      <geometry>
        <mesh filename="package://aros_description/meshes/right_arm/fingers/finger3/link2/body.dae" />
      </geometry> 
      <!-- <origin xyz="4.7 0.965 1.37" rpy="0 0 0" /> --> 
   </visual>
  </link> 
  
  <link name="right_finger3_tip_link">
    <visual>
      <geometry>
        <mesh filename="package://aros_description/meshes/right_arm/fingers/finger3/tip/body.dae" />
      </geometry> 
      <!-- <origin xyz="4.7 0.965 1.37" rpy="0 0 0" /> --> 
   </visual>
  </link> 
  
   <joint name="base_to_torso" type="fixed">
    <parent link="base_link"/>
    <child link="torso_link"/>
    <origin xyz="0 0 1.203" rpy="0 0 0" />
  </joint>
  
   <joint name="torso_to_pan_body" type="fixed">
    <parent link="torso_link"/>
    <child link="pan_body_link"/>
    <origin xyz="0 0.005 0.447" rpy="0 0 0" />
  </joint>
  
   <joint name="pan_body_to_neck" type="fixed">
    <parent link="pan_body_link"/>
    <child link="neck_link"/>
    <origin xyz="0 0 0.044" rpy="0 0 0" />
  </joint>
  
  <joint name="neck_to_vision" type="fixed">
    <parent link="neck_link"/>
    <child link="vision_link"/>
    <origin xyz="0 0 0.0503" rpy="0 0 0" />
  </joint>
  
  <joint name="torso_to_right_joint0" type="fixed">
    <parent link="torso_link"/>
    <child link="right_arm0_link"/>
    <origin xyz="0 0.045 0.297" rpy="-1.57 -3.14 0" />
  </joint>
 
  <joint name="right_joint0" type="revolute">
    <axis xyz="0 0 1"/>
    <limit effort="160.0" lower="-2.62" upper="1.57" velocity="0.5"/>
    <parent link="right_arm0_link"/>
    <child link="right_arm1_link"/>
    <origin xyz="0 0 0.2" rpy="0 0 0" />
  </joint>

 
  <joint name="right_joint1" type="revolute">
    <axis xyz="0 0 1"/>
    <limit effort="160.0" lower="-1.66" upper="0.79" velocity="0.5"/>
    <parent link="right_arm1_link"/>
    <child link="right_arm2_link"/>
    <origin xyz="0 0 0.14" rpy="1.57 1.57 0" />
  </joint>
  
   <joint name="right_joint2" type="revolute">
    <axis xyz="0 0 1"/>
    <limit effort="160.0" lower="-1.57" upper="2.44" velocity="0.5"/>
    <parent link="right_arm2_link"/>
    <child link="right_arm3_link"/>
    <origin xyz="-0.195 0 0" rpy="-1.57 0 1.57" />
  </joint>
  
   <joint name="right_joint3" type="revolute">
    <axis xyz="0 0 1"/>
    <limit effort="160.0" lower="-2.88" upper="0.26" velocity="0.5"/>
    <parent link="right_arm3_link"/>
    <child link="right_arm4_link"/>
    <origin xyz="0 0 0.2" rpy="1.57 1.57 0"/>
  </joint>
  
  <joint name="right_joint4" type="revolute">
    <axis xyz="0 0 1"/>
    <limit effort="160.0" lower="-2.88" upper="2.88" velocity="0.5"/>
    <parent link="right_arm4_link"/>
    <child link="right_arm5_link"/>
    <origin xyz="-0.208 0 0" rpy="-1.57 0 1.57" />
  </joint>
  
  <joint name="right_joint5" type="revolute">
    <axis xyz="0 0 1"/>
    <limit effort="160.0" lower="-2.09" upper="2.09" velocity="0.5"/>
    <parent link="right_arm5_link"/>
    <child link="right_arm6_link"/>
    <origin xyz="0 0 0.161" rpy="1.57 1.57 0"/>
  </joint>
  
  <joint name="right_joint6" type="revolute">
    <axis xyz="0 0 1"/>
    <limit effort="160.0" lower="-1.57" upper="2.88" velocity="0.5"/>
    <parent link="right_arm6_link"/>
    <child link="right_arm7_link"/>
    <origin xyz="-0.053 0 0" rpy="-1.57 0 1.57" />
  </joint>
  
  <joint name="right_fixed_joint1" type="fixed">
    <parent link="right_arm7_link"/>
    <child link="right_fts_link"/>
    <origin xyz="0 0 0.065" rpy="-1.57 -1.57 0"/>
  </joint>
  
  <joint name="right_fixed_joint2" type="fixed">
    <parent link="right_fts_link"/>
    <child link="right_adapter_link"/>
    <origin xyz="0.04 0 0" rpy="0 0 0"/>
  </joint>
  
  <joint name="right_fixed_joint3" type="fixed">
    <parent link="right_adapter_link"/>
    <child link="right_hand_link"/>
    <origin xyz="0.06 0 0" rpy="0 0 0"/>
  </joint>
  
  <joint name="right_fixed_joint4" type="fixed">
    <parent link="right_hand_link"/>
    <child link="right_hand_sensor_link"/>
    <origin xyz="0.035 0 0" rpy="0 0 0"/>
  </joint>
  
  <!-- finger 1-->
  <joint name="right_finger1_base_joint" type="revolute">
    <axis xyz="0 0 1"/>
    <limit effort="160.0" lower="0" upper="3.14" velocity="0.5"/>
    <parent link="right_hand_link"/>
    <child link="right_finger1_base_link"/>
    <origin xyz="0 -0.025 0" rpy="0 1.57 0"/>
  </joint>
  <!-- finger 2-->
  
  <!-- finger 3 -->
  <joint name="right_finger3_joint1" type="revolute">
    <axis xyz="0 0 1"/>
    <limit effort="160.0" lower="0" upper="2.44" velocity="0.5"/>
    <parent link="right_hand_link"/>
    <child link="right_finger3_1_link"/>
    <origin xyz="0.03 0 -0.05" rpy="1.57 3.14 0"/>
  </joint>
  
  <joint name="right_finger3_joint2" type="revolute">
    <axis xyz="0 0 1"/>
    <limit effort="160.0" lower="0" upper="0.79" velocity="0.5"/>
    <parent link="right_finger3_1_link"/>
    <child link="right_finger3_2_link"/>
    <origin xyz="-0.005 0.07 0" rpy="0 0 0"/>
  </joint>
  
   <joint name="right_fixed_joint5" type="fixed">
    <parent link="right_finger3_2_link"/>
    <child link="right_finger3_tip_link"/>
    <origin xyz="-0.028 0.022 0" rpy="0 0 1.97"/>
  </joint>

  
</robot>