<?xml version="1.0" ?>
<!-- =================================================================================== -->
<!-- |    This document was autogenerated by xacro from aros.urdf.xacro                | -->
<!-- |    EDITING THIS FILE BY HAND IS NOT RECOMMENDED                                 | -->
<!-- =================================================================================== -->
<robot name="aros" xmlns:controller="http://playerstage.sourceforge.net/gazebo/xmlschema/#controller" xmlns:interface="http://playerstage.sourceforge.net/gazebo/xmlschema/#interface" xmlns:sensor="http://playerstage.sourceforge.net/gazebo/xmlschema/#sensor" xmlns:xacro="http://ros.org/wiki/xacro">
  <!-- ********** Torso ********** -->
  <!-- Torso Location: Add to the transform from base to torso -->
  <!-- ********** Pan tilt ********** -->
  <!-- Pan tilt Location: Add to the transform from torso to pan_tilt-->
  <!-- ********** Neck ********** -->
  <!-- Neck Location: Add to the transform from pan_tilt to neck-->
  <!-- ********** Vision ********** -->
  <!-- Vision Location: Add to the transform from neck to vision-->
  <!-- ********** arm link 0 ********** -->
  <!-- arm link 0 Location: add to the transform from torso to right arm 0-->
  <!-- ********** arm link 1 ********** -->
  <!-- arm link 1 Location: add to the transform from right arm 0 to right arm 1-->
  <!-- arm joint 1 limits : add the joint limits of the right arm link 1-->
  <!-- ********** arm link 2 ********** -->
  <!-- arm link 2 Location: add to the transform from right arm 1 to right arm 2-->
  <!-- arm joint 2 limits : add the joint limits of the right arm link 2-->
  <!-- ********** arm link 3 ********** -->
  <!-- arm link 3 Location: add to the transform from right arm 2 to right arm 3-->
  <!-- arm joint 3 limits : add the joint limits of the right arm link 3-->
  <!-- ********** arm link 4 ********** -->
  <!-- arm link 4 Location: add to the transform from right arm 3 to right arm 4 -->
  <!-- arm joint 4 limits : add the joint limits of the right arm link 4 -->
  <!-- ********** arm link 5 ********** -->
  <!-- arm link 5 Location: add to the transform from right arm 4 to right arm 5-->
  <!-- arm joint 5 limits : add the joint limits of the right arm link 5 -->
  <!-- ********** arm link 6 ********** -->
  <!-- arm link 6 Location: add to the transform from right arm 5 to right arm 6-->
  <!-- arm joint 6 limits : add the joint limits of the right arm link 6 -->
  <!-- ********** arm link 7 ********** -->
  <!-- arm link 7 Location: add to the transform from right arm 6 to right arm 7-->
  <!-- arm joint 7 limits : add the joint limits of the right arm link 7 -->
  <!-- ********** hand link fts ********** -->
  <!-- hand link fts Location: add to the transform from right arm 7 to right hand fts -->
  <!-- ********** hand link adapter ********** -->
  <!-- hand link adapter Location: add to the transform from right hand fts to right hand adapter -->
  <!-- ********** hand link barrett ********** -->
  <!-- hand link barrett Location: add to the transform from right hand adapter to right hand barrett -->
  <!-- <property name="hand_barrett_roll" value="0.0" /> -->
  <!--<property name="hand_barrett_yaw" value="0.0" /> -->
  <!-- ********** hand link sensor ********** -->
  <!-- hand link sensor Location: add to the transform from right hand barrett to right hand sensor -->
  <!-- ********** finger  base link ********** -->
  <!-- finger base link Location: add to the transform from right hand barrett to right hand finger base -->
  <!-- finger base limits : add the joint limits of the right finger base -->
  <!-- ********** finger 1 link ********** -->
  <!-- finger 1 link Location: add to the transform from right hand finger 1 base to right hand finger 1 -->
  <!-- finger 1 limits : add the joint limits of the right finger 1 -->
  <!-- ********** finger 2 link ********** -->
  <!-- finger 2 link Location: add to the transform from right hand finger 1 to right hand finger 2 -->
  <!-- finger 2 limits : add the joint limits of the right finger 2 -->
  <!-- ********** finger tip link ********** -->
  <!-- finger tip link Location: add to the transform from right hand finger 2 to right hand finger tip -->
  <!-- ********** Torso ********** -->
  <!-- Torso Location: Add to the transform from base to torso -->
  <!-- ********** Pan tilt ********** -->
  <!-- Pan tilt Location: Add to the transform from torso to pan_tilt-->
  <!-- ********** Neck ********** -->
  <!-- Neck Location: Add to the transform from pan_tilt to neck-->
  <!-- ********** Vision ********** -->
  <!-- Vision Location: Add to the transform from neck to vision-->
  <!-- ********** arm link 0 ********** -->
  <!-- arm link 0 Location: add to the transform from torso to right arm 0-->
  <!-- ********** arm link 1 ********** -->
  <!-- arm link 1 Location: add to the transform from right arm 0 to right arm 1-->
  <!-- arm joint 1 limits : add the joint limits of the right arm link 1-->
  <!-- ********** arm link 2 ********** -->
  <!-- arm link 2 Location: add to the transform from right arm 1 to right arm 2-->
  <!-- arm joint 2 limits : add the joint limits of the right arm link 2-->
  <!-- ********** arm link 3 ********** -->
  <!-- arm link 3 Location: add to the transform from right arm 2 to right arm 3-->
  <!-- arm joint 3 limits : add the joint limits of the right arm link 3-->
  <!-- ********** arm link 4 ********** -->
  <!-- arm link 4 Location: add to the transform from right arm 3 to right arm 4 -->
  <!-- arm joint 4 limits : add the joint limits of the right arm link 4 -->
  <!-- ********** arm link 5 ********** -->
  <!-- arm link 5 Location: add to the transform from right arm 4 to right arm 5-->
  <!-- arm joint 5 limits : add the joint limits of the right arm link 5 -->
  <!-- ********** arm link 6 ********** -->
  <!-- arm link 6 Location: add to the transform from right arm 5 to right arm 6-->
  <!-- arm joint 6 limits : add the joint limits of the right arm link 6 -->
  <!-- ********** arm link 7 ********** -->
  <!-- arm link 7 Location: add to the transform from right arm 6 to right arm 7-->
  <!-- arm joint 7 limits : add the joint limits of the right arm link 7 -->
  <!-- ********** hand link fts ********** -->
  <!-- hand link fts Location: add to the transform from right arm 7 to right hand fts -->
  <!-- ********** hand link adapter ********** -->
  <!-- hand link adapter Location: add to the transform from right hand fts to right hand adapter -->
  <!-- ********** hand link barrett ********** -->
  <!-- hand link barrett Location: add to the transform from right hand adapter to right hand barrett -->
  <!-- <property name="hand_barrett_roll" value="0.0" /> -->
  <!--<property name="hand_barrett_yaw" value="0.0" /> -->
  <!-- ********** hand link sensor ********** -->
  <!-- hand link sensor Location: add to the transform from right hand barrett to right hand sensor -->
  <!-- ********** finger  base link ********** -->
  <!-- finger base link Location: add to the transform from right hand barrett to right hand finger base -->
  <!-- finger base limits : add the joint limits of the right finger base -->
  <!-- ********** finger 1 link ********** -->
  <!-- finger 1 link Location: add to the transform from right hand finger 1 base to right hand finger 1 -->
  <!-- finger 1 limits : add the joint limits of the right finger 1 -->
  <!-- ********** finger 2 link ********** -->
  <!-- finger 2 link Location: add to the transform from right hand finger 1 to right hand finger 2 -->
  <!-- finger 2 limits : add the joint limits of the right finger 2 -->
  <!-- ********** finger tip link ********** -->
  <!-- finger tip link Location: add to the transform from right hand finger 2 to right hand finger tip -->
  <!-- ********** Torso ********** -->
  <!-- Torso Location: Add to the transform from base to torso -->
  <!-- ********** Pan tilt ********** -->
  <!-- Pan tilt Location: Add to the transform from torso to pan_tilt-->
  <!-- ********** Neck ********** -->
  <!-- Neck Location: Add to the transform from pan_tilt to neck-->
  <!-- ********** Vision ********** -->
  <!-- Vision Location: Add to the transform from neck to vision-->
  <!-- ********** arm link 0 ********** -->
  <!-- arm link 0 Location: add to the transform from torso to right arm 0-->
  <!-- ********** arm link 1 ********** -->
  <!-- arm link 1 Location: add to the transform from right arm 0 to right arm 1-->
  <!-- arm joint 1 limits : add the joint limits of the right arm link 1-->
  <!-- ********** arm link 2 ********** -->
  <!-- arm link 2 Location: add to the transform from right arm 1 to right arm 2-->
  <!-- arm joint 2 limits : add the joint limits of the right arm link 2-->
  <!-- ********** arm link 3 ********** -->
  <!-- arm link 3 Location: add to the transform from right arm 2 to right arm 3-->
  <!-- arm joint 3 limits : add the joint limits of the right arm link 3-->
  <!-- ********** arm link 4 ********** -->
  <!-- arm link 4 Location: add to the transform from right arm 3 to right arm 4 -->
  <!-- arm joint 4 limits : add the joint limits of the right arm link 4 -->
  <!-- ********** arm link 5 ********** -->
  <!-- arm link 5 Location: add to the transform from right arm 4 to right arm 5-->
  <!-- arm joint 5 limits : add the joint limits of the right arm link 5 -->
  <!-- ********** arm link 6 ********** -->
  <!-- arm link 6 Location: add to the transform from right arm 5 to right arm 6-->
  <!-- arm joint 6 limits : add the joint limits of the right arm link 6 -->
  <!-- ********** arm link 7 ********** -->
  <!-- arm link 7 Location: add to the transform from right arm 6 to right arm 7-->
  <!-- arm joint 7 limits : add the joint limits of the right arm link 7 -->
  <!-- ********** hand link fts ********** -->
  <!-- hand link fts Location: add to the transform from right arm 7 to right hand fts -->
  <!-- ********** hand link adapter ********** -->
  <!-- hand link adapter Location: add to the transform from right hand fts to right hand adapter -->
  <!-- ********** hand link barrett ********** -->
  <!-- hand link barrett Location: add to the transform from right hand adapter to right hand barrett -->
  <!-- <property name="hand_barrett_roll" value="0.0" /> -->
  <!--<property name="hand_barrett_yaw" value="0.0" /> -->
  <!-- ********** hand link sensor ********** -->
  <!-- hand link sensor Location: add to the transform from right hand barrett to right hand sensor -->
  <!-- ********** finger  base link ********** -->
  <!-- finger base link Location: add to the transform from right hand barrett to right hand finger base -->
  <!-- finger base limits : add the joint limits of the right finger base -->
  <!-- ********** finger 1 link ********** -->
  <!-- finger 1 link Location: add to the transform from right hand finger 1 base to right hand finger 1 -->
  <!-- finger 1 limits : add the joint limits of the right finger 1 -->
  <!-- ********** finger 2 link ********** -->
  <!-- finger 2 link Location: add to the transform from right hand finger 1 to right hand finger 2 -->
  <!-- finger 2 limits : add the joint limits of the right finger 2 -->
  <!-- ********** finger tip link ********** -->
  <!-- finger tip link Location: add to the transform from right hand finger 2 to right hand finger tip -->
  <link name="base_link">
    <visual>
      <origin rpy="0 0 0" xyz="0 0 0"/>
      <geometry>
        <mesh filename="package://aros_description/meshes/base/body.dae"/>
      </geometry>
    </visual>
    <collision>
      <origin rpy="0 0 0" xyz="0 0 0"/>
      <geometry>
        <mesh filename="package://aros_description/meshes/base/link.dae"/>
      </geometry>
    </collision>
  </link>
  <link name="torso_link">
    <visual>
      <geometry>
        <mesh filename="package://aros_description/meshes/torso/body.dae"/>
      </geometry>
    </visual>
  </link>
  <joint name="base_to_torso" type="fixed">
    <parent link="base_link"/>
    <child link="torso_link"/>
    <origin rpy="0.0 0.0 0.0" xyz="0.0 0.0 1.203"/>
  </joint>
  <link name="pan_tilt_link">
    <visual>
      <geometry>
        <mesh filename="package://aros_description/meshes/pan_tilt/body.dae"/>
      </geometry>
    </visual>
  </link>
  <joint name="torso_to_pan_tilt" type="fixed">
    <parent link="torso_link"/>
    <child link="pan_tilt_link"/>
    <origin rpy="0.0 0.0 0.0" xyz="0.0 0.005 0.447"/>
  </joint>
  <link name="neck_link">
    <visual>
      <geometry>
        <mesh filename="package://aros_description/meshes/neck/body.dae"/>
      </geometry>
    </visual>
  </link>
  <joint name="pan_tilt_to_neck" type="fixed">
    <parent link="pan_tilt_link"/>
    <child link="neck_link"/>
    <origin rpy="0.0 0.0 0.0" xyz="0.0 0.0 0.044"/>
  </joint>
  <link name="vision_link">
    <visual>
      <geometry>
        <mesh filename="package://aros_description/meshes/vision/body.dae"/>
      </geometry>
    </visual>
  </link>
  <joint name="neck_to_vision" type="fixed">
    <parent link="neck_link"/>
    <child link="vision_link"/>
    <origin rpy="0.0 0.0 0.0" xyz="0.0 0.0 0.0503"/>
  </joint>
  <!-- Right arm and hand -->
  <link name="right_arm0_link">
    <visual>
      <geometry>
        <mesh filename="package://aros_description/meshes/arm/link0/body.dae"/>
      </geometry>
    </visual>
    <collision>
      <geometry>
        <mesh filename="package://aros_description/meshes/arm/link0/link.dae"/>
      </geometry>
    </collision>
  </link>
  <joint name="torso_to_right_arm0" type="fixed">
    <parent link="torso_link"/>
    <child link="right_arm0_link"/>
    <origin rpy="-1.57079632679 -3.14159265359 0.0" xyz="0.0 0.045 0.297"/>
  </joint>
  <link name="right_arm1_link">
    <visual>
      <geometry>
        <mesh filename="package://aros_description/meshes/arm/link1/body.dae"/>
      </geometry>
    </visual>
    <collision>
      <geometry>
        <mesh filename="package://aros_description/meshes/arm/link1/link.dae"/>
      </geometry>
    </collision>
  </link>
  <joint name="right_joint1" type="revolute">
    <axis xyz="0 0 1"/>
    <limit effort="160.0" lower="-2.61799387799" upper="1.57079632679" velocity="0.5"/>
    <parent link="right_arm0_link"/>
    <child link="right_arm1_link"/>
    <origin rpy="0.0 0.0 0.0" xyz="0.0 0.0 0.2"/>
  </joint>
  <link name="right_arm2_link">
    <visual>
      <geometry>
        <mesh filename="package://aros_description/meshes/arm/link2/body.dae"/>
      </geometry>
    </visual>
    <collision>
      <geometry>
        <mesh filename="package://aros_description/meshes/arm/link2/link.dae"/>
      </geometry>
    </collision>
  </link>
  <joint name="right_joint2" type="revolute">
    <axis xyz="0 0 1"/>
    <limit effort="160.0" lower="-1.65806278939" upper="0.785398163397" velocity="0.5"/>
    <parent link="right_arm1_link"/>
    <child link="right_arm2_link"/>
    <origin rpy="1.57079632679 1.57079632679 0.0" xyz="0.0 0.0 0.14"/>
  </joint>
  <link name="right_arm3_link">
    <visual>
      <geometry>
        <mesh filename="package://aros_description/meshes/arm/link3/body.dae"/>
      </geometry>
    </visual>
    <collision>
      <geometry>
        <mesh filename="package://aros_description/meshes/arm/link3/link.dae"/>
      </geometry>
    </collision>
  </link>
  <joint name="right_joint3" type="revolute">
    <axis xyz="0 0 1"/>
    <limit effort="160.0" lower="-1.57079632679" upper="2.44346095279" velocity="0.5"/>
    <parent link="right_arm2_link"/>
    <child link="right_arm3_link"/>
    <origin rpy="-1.57079632679 0.0 1.57079632679" xyz="-0.195 0.0 0.0"/>
  </joint>
  <link name="right_arm4_link">
    <visual>
      <geometry>
        <mesh filename="package://aros_description/meshes/arm/link4/body.dae"/>
      </geometry>
    </visual>
    <collision>
      <geometry>
        <mesh filename="package://aros_description/meshes/arm/link4/link.dae"/>
      </geometry>
    </collision>
  </link>
  <joint name="right_joint4" type="revolute">
    <axis xyz="0 0 1"/>
    <limit effort="160.0" lower="-2.87979326579" upper="0.261799387799" velocity="0.5"/>
    <parent link="right_arm3_link"/>
    <child link="right_arm4_link"/>
    <origin rpy="1.57079632679 1.57079632679 0.0" xyz="0.0 0.0 0.2"/>
  </joint>
  <link name="right_arm5_link">
    <visual>
      <geometry>
        <mesh filename="package://aros_description/meshes/arm/link5/body.dae"/>
      </geometry>
    </visual>
    <collision>
      <geometry>
        <mesh filename="package://aros_description/meshes/arm/link5/link.dae"/>
      </geometry>
    </collision>
  </link>
  <joint name="right_joint5" type="revolute">
    <axis xyz="0 0 1"/>
    <limit effort="160.0" lower="-2.87979326579" upper="2.87979326579" velocity="0.5"/>
    <parent link="right_arm4_link"/>
    <child link="right_arm5_link"/>
    <origin rpy="-1.57079632679 0.0 1.57079632679" xyz="-0.208 0.0 0.0"/>
  </joint>
  <link name="right_arm6_link">
    <visual>
      <geometry>
        <mesh filename="package://aros_description/meshes/arm/link6/body.dae"/>
      </geometry>
    </visual>
    <collision>
      <geometry>
        <mesh filename="package://aros_description/meshes/arm/link6/link.dae"/>
      </geometry>
    </collision>
  </link>
  <joint name="right_joint6" type="revolute">
    <axis xyz="0 0 1"/>
    <limit effort="160.0" lower="-2.09439510239" upper="2.09439510239" velocity="0.5"/>
    <parent link="right_arm5_link"/>
    <child link="right_arm6_link"/>
    <origin rpy="1.57079632679 1.57079632679 0.0" xyz="0.0 0.0 0.161"/>
  </joint>
  <link name="right_arm7_link">
    <visual>
      <geometry>
        <mesh filename="package://aros_description/meshes/arm/link7/body.dae"/>
      </geometry>
    </visual>
    <collision>
      <geometry>
        <mesh filename="package://aros_description/meshes/arm/link7/link.dae"/>
      </geometry>
    </collision>
  </link>
  <joint name="right_joint7" type="revolute">
    <axis xyz="0 0 1"/>
    <limit effort="160.0" lower="-1.57079632679" upper="2.87979326579" velocity="0.5"/>
    <parent link="right_arm6_link"/>
    <child link="right_arm7_link"/>
    <origin rpy="-1.57079632679 0.0 1.57079632679" xyz="-0.053 0.0 0.0"/>
  </joint>
  <!--
   <xacro:aros_fixed_v0 name="right_arm7" parent="right_arm6">
   <origin xyz="${arm7_x} ${arm7_y} ${arm7_z}" rpy="${arm7_roll} ${arm7_pitch} ${arm7_yaw}" />
   </xacro:aros_fixed_v0>
-->
  <!--
	<link name="right_arm7_link">
	 <visual>
        <geometry>
              <mesh filename="package://aros_description/meshes/arm/link7/body.dae" />
        </geometry>
      </visual>
	<collision>
      <geometry>
        <mesh filename="package://aros_description/meshes/arm/link7/link.dae" />
      </geometry>
    </collision>
    </link>	
	
  <joint name="right_arm6_link_to_right_arm7_link" type="fixed">
    <parent link="right_arm6_link"/>
    <child link="right_arm7_link"/>
    <origin xyz="${arm7_x} ${arm7_y} ${arm7_z}" rpy="${arm7_roll} ${arm7_pitch} ${arm7_yaw}" />
  </joint>
	-->
  <link name="right_hand_fts_link">
    <visual>
      <geometry>
        <mesh filename="package://aros_description/meshes/hand/hand_fts/body.dae"/>
      </geometry>
    </visual>
    <collision>
      <geometry>
        <mesh filename="package://aros_description/meshes/hand/hand_fts/link.dae"/>
      </geometry>
    </collision>
  </link>
  <joint name="right_arm7_to_right_hand_fts" type="fixed">
    <parent link="right_arm7_link"/>
    <child link="right_hand_fts_link"/>
    <origin rpy="-1.57079632679 -1.57079632679 0.0" xyz="0.0 0.0 0.065"/>
  </joint>
  <link name="right_hand_adapter_link">
    <visual>
      <geometry>
        <mesh filename="package://aros_description/meshes/hand/hand_adapter/body.dae"/>
      </geometry>
    </visual>
  </link>
  <joint name="right_hand_fts_to_right_hand_adapter" type="fixed">
    <parent link="right_hand_fts_link"/>
    <child link="right_hand_adapter_link"/>
    <origin rpy="0.0 0.0 0.0" xyz="0.04 0.0 0.0"/>
  </joint>
  <link name="right_hand_barrett_link">
    <visual>
      <geometry>
        <mesh filename="package://aros_description/meshes/hand/hand_barrett/body.dae"/>
      </geometry>
    </visual>
    <collision>
      <geometry>
        <mesh filename="package://aros_description/meshes/hand/hand_barrett/link.dae"/>
      </geometry>
    </collision>
  </link>
  <joint name="right_hand_adapter_to_right_hand_barrett" type="fixed">
    <parent link="right_hand_adapter_link"/>
    <child link="right_hand_barrett_link"/>
    <origin rpy="1.57079632679 0.0 1.57079632679" xyz="0.088 0.0 0.0"/>
  </joint>
  <!--
	<xacro:aros_arm_v0 prefix="right" name="hand_barrett" parent="hand_adapter" link="7" revolute="true" lower="${arm7_lower}" upper="${arm7_upper}">
    <origin xyz="${hand_barrett_x} ${hand_barrett_y} ${hand_barrett_z}" rpy="${hand_barrett_roll} ${hand_barrett_pitch} ${hand_barrett_yaw}" />
   </xacro:aros_arm_v0>	
-->
  <!--
	 <link name="right_hand_barrett_link">
	 <visual>
        <geometry>
              <mesh filename="package://aros_description/meshes/hand/hand_barrett/body.dae" />
        </geometry>
      </visual>		
	<collision>
      <geometry>
        <mesh filename="package://aros_description/meshes/hand/hand_barrett/link.dae" />
      </geometry>
    </collision>
    </link>	

	 <joint name="right_joint7" type="revolute">
		<axis xyz="0 0 1"/>
		<limit effort="${EFFORT}" lower="${arm7_lower}" upper="${arm7_upper}" velocity="${VELOCITY}"/>
		<parent link="right_hand_adapter_link"/>
		<child link="right_hand_barrett_link"/>
		<origin xyz="${hand_barrett_x} ${hand_barrett_y} ${hand_barrett_z}" rpy="${hand_barrett_roll} ${hand_barrett_pitch} ${hand_barrett_yaw}" />
	  </joint>
-->
  <link name="right_hand_sensor_link">
    <visual>
      <geometry>
        <mesh filename="package://aros_description/meshes/hand/hand_sensor/body.dae"/>
      </geometry>
    </visual>
    <collision>
      <geometry>
        <mesh filename="package://aros_description/meshes/hand/hand_sensor/link.dae"/>
      </geometry>
    </collision>
  </link>
  <joint name="right_hand_barrett_to_right_hand_sensor" type="fixed">
    <parent link="right_hand_barrett_link"/>
    <child link="right_hand_sensor_link"/>
    <origin rpy="0.0 0.0 0.0" xyz="0.0 0.0 0.0"/>
  </joint>
  <!--
  <link name="right_hand_sensor_link">
	 <visual>
        <geometry>
              <mesh filename="package://aros_description/meshes/hand/hand_sensor/body.dae" />
        </geometry>
      </visual>		
		<collision>
		  <geometry>
			<mesh filename="package://aros_description/meshes/hand/hand_sensor/link.dae" />
		  </geometry>
		</collision>
    </link>		
  <joint name="right_endpoint" type="fixed">
    <parent link="right_hand_barrett_link"/>
    <child link="right_hand_sensor_link"/>
    <origin xyz="${hand_sensor_x} ${hand_sensor_y} ${hand_sensor_z}" rpy="${hand_sensor_roll} ${hand_sensor_pitch} ${hand_sensor_yaw}" />
  </joint>
-->
  <!-- finger 1 -->
  <link name="right_finger1_base_link">
    <visual>
      <geometry>
        <mesh filename="package://aros_description/meshes/hand/finger/base/body.dae"/>
      </geometry>
    </visual>
    <collision>
      <geometry>
        <mesh filename="package://aros_description/meshes/hand/finger/base/link.dae"/>
      </geometry>
    </collision>
  </link>
  <joint name="right_finger1_joint_base" type="revolute">
    <axis xyz="0 0 1"/>
    <limit effort="160.0" lower="0.0" upper="3.14159265359" velocity="0.5"/>
    <parent link="right_hand_sensor_link"/>
    <child link="right_finger1_base_link"/>
    <origin rpy="0.0 0.0 -1.57079632679" xyz="-0.025 0.0 -0.028"/>
  </joint>
  <link name="right_finger1_1_link">
    <visual>
      <geometry>
        <mesh filename="package://aros_description/meshes/hand/finger/link1/body.dae"/>
      </geometry>
    </visual>
    <collision>
      <geometry>
        <mesh filename="package://aros_description/meshes/hand/finger/link1/link.dae"/>
      </geometry>
    </collision>
  </link>
  <joint name="right_finger1_joint1" type="revolute">
    <axis xyz="0 0 1"/>
    <limit effort="160.0" lower="0.0" upper="2.44346095279" velocity="0.5"/>
    <parent link="right_finger1_base_link"/>
    <child link="right_finger1_1_link"/>
    <origin rpy="0.0 1.57079632679 1.57079632679" xyz="-0.05 0.0 0.036"/>
  </joint>
  <link name="right_finger1_2_link">
    <visual>
      <geometry>
        <mesh filename="package://aros_description/meshes/hand/finger/link2/body.dae"/>
      </geometry>
    </visual>
    <collision>
      <geometry>
        <mesh filename="package://aros_description/meshes/hand/finger/link2/link.dae"/>
      </geometry>
    </collision>
  </link>
  <joint name="right_finger1_joint2" type="revolute">
    <axis xyz="0 0 1"/>
    <limit effort="160.0" lower="0.0" upper="0.785398163397" velocity="0.5"/>
    <parent link="right_finger1_1_link"/>
    <child link="right_finger1_2_link"/>
    <origin rpy="0.0 0.0 0.0" xyz="-0.005 0.07 0.0"/>
  </joint>
  <!--	
	<link name="${prefix}_finger1_tip_link">
	 <visual>
        <geometry>
              <mesh filename="package://aros_description/meshes/hand/finger/tip/body.dae" />
        </geometry>
      </visual>		
	</link>
	
  <joint name="${prefix}_finger1_joint_tip" type="fixed">
    <parent link="${prefix}_finger1_2_link"/>
    <child link="${prefix}_finger1_tip_link"/>
    <origin xyz="${finger_tip_x} ${finger_tip_y} ${finger_tip_z}" rpy="${finger_tip_roll} ${finger_tip_pitch} ${finger_tip_yaw}"/>
  </joint>
-->
  <!-- finger 2 -->
  <link name="right_finger2_base_link">
    <visual>
      <geometry>
        <mesh filename="package://aros_description/meshes/hand/finger/base/body.dae"/>
      </geometry>
    </visual>
    <collision>
      <geometry>
        <mesh filename="package://aros_description/meshes/hand/finger/base/link.dae"/>
      </geometry>
    </collision>
  </link>
  <joint name="right_finger2_joint_base" type="revolute">
    <axis xyz="0 0 1"/>
    <limit effort="160.0" lower="-3.14159265359" upper="-0.0" velocity="0.5"/>
    <parent link="right_hand_sensor_link"/>
    <child link="right_finger2_base_link"/>
    <origin rpy="0.0 0.0 -1.57079632679" xyz="0.025 0.0 -0.028"/>
  </joint>
  <link name="right_finger2_1_link">
    <visual>
      <geometry>
        <mesh filename="package://aros_description/meshes/hand/finger/link1/body.dae"/>
      </geometry>
    </visual>
    <collision>
      <geometry>
        <mesh filename="package://aros_description/meshes/hand/finger/link1/link.dae"/>
      </geometry>
    </collision>
  </link>
  <joint name="right_finger2_joint1" type="revolute">
    <axis xyz="0 0 1"/>
    <limit effort="160.0" lower="0.0" upper="2.44346095279" velocity="0.5"/>
    <parent link="right_finger2_base_link"/>
    <child link="right_finger2_1_link"/>
    <origin rpy="0.0 1.57079632679 1.57079632679" xyz="-0.05 0.0 0.036"/>
  </joint>
  <link name="right_finger2_2_link">
    <visual>
      <geometry>
        <mesh filename="package://aros_description/meshes/hand/finger/link2/body.dae"/>
      </geometry>
    </visual>
    <collision>
      <geometry>
        <mesh filename="package://aros_description/meshes/hand/finger/link2/link.dae"/>
      </geometry>
    </collision>
  </link>
  <joint name="right_finger2_joint2" type="revolute">
    <axis xyz="0 0 1"/>
    <limit effort="160.0" lower="0.0" upper="0.785398163397" velocity="0.5"/>
    <parent link="right_finger2_1_link"/>
    <child link="right_finger2_2_link"/>
    <origin rpy="0.0 0.0 0.0" xyz="-0.005 0.07 0.0"/>
  </joint>
  <!--
	<link name="${prefix}_finger2_tip_link">
	 <visual>
        <geometry>
              <mesh filename="package://aros_description/meshes/hand/finger/tip/body.dae" />
        </geometry>
      </visual>		
	</link>
	
  <joint name="${prefix}_finger2_joint_tip" type="fixed">
    <parent link="${prefix}_finger2_2_link"/>
    <child link="${prefix}_finger2_tip_link"/>
    <origin xyz="${finger_tip_x} ${finger_tip_y} ${finger_tip_z}" rpy="${finger_tip_roll} ${finger_tip_pitch} ${finger_tip_yaw}"/>
  </joint>
-->
  <!-- finger 3 -->
  <link name="right_finger3_1_link">
    <visual>
      <geometry>
        <mesh filename="package://aros_description/meshes/hand/finger/link1/body.dae"/>
      </geometry>
    </visual>
    <collision>
      <geometry>
        <mesh filename="package://aros_description/meshes/hand/finger/link1/link.dae"/>
      </geometry>
    </collision>
  </link>
  <joint name="right_finger3_joint1" type="revolute">
    <axis xyz="0 0 1"/>
    <limit effort="160.0" lower="0.0" upper="2.44346095279" velocity="0.5"/>
    <parent link="right_hand_sensor_link"/>
    <child link="right_finger3_1_link"/>
    <origin rpy="-1.57079632679 1.57079632679 1.57079632679" xyz="0.0 -0.05 0.008"/>
  </joint>
  <link name="right_finger3_2_link">
    <visual>
      <geometry>
        <mesh filename="package://aros_description/meshes/hand/finger/link2/body.dae"/>
      </geometry>
    </visual>
    <collision>
      <geometry>
        <mesh filename="package://aros_description/meshes/hand/finger/link2/link.dae"/>
      </geometry>
    </collision>
  </link>
  <joint name="right_finger3_joint2" type="revolute">
    <axis xyz="0 0 1"/>
    <limit effort="160.0" lower="0.0" upper="0.785398163397" velocity="0.5"/>
    <parent link="right_finger3_1_link"/>
    <child link="right_finger3_2_link"/>
    <origin rpy="0.0 0.0 0.0" xyz="-0.005 0.07 0.0"/>
  </joint>
  <!--	
	<link name="${prefix}_finger3_tip_link">
	 <visual>
        <geometry>
              <mesh filename="package://aros_description/meshes/hand/finger/tip/body.dae" />
        </geometry>
      </visual>		
	</link>
	
  <joint name="${prefix}_finger3_joint_tip" type="fixed">
    <parent link="${prefix}_finger3_2_link"/>
    <child link="${prefix}_finger3_tip_link"/>
    <origin xyz="${finger_tip_x} ${finger_tip_y} ${finger_tip_z}" rpy="${finger_tip_roll} ${finger_tip_pitch} ${finger_tip_yaw}"/>
  </joint>
-->
  <!-- Left arm-->
  <link name="left_arm0_link">
    <visual>
      <geometry>
        <mesh filename="package://aros_description/meshes/arm/link0/body.dae"/>
      </geometry>
    </visual>
    <collision>
      <geometry>
        <mesh filename="package://aros_description/meshes/arm/link0/link.dae"/>
      </geometry>
    </collision>
  </link>
  <joint name="torso_to_left_arm0" type="fixed">
    <parent link="torso_link"/>
    <child link="left_arm0_link"/>
    <origin rpy="1.57079632679 -3.14159265359 0.0" xyz="0.0 -0.045 0.297"/>
  </joint>
  <link name="left_arm1_link">
    <visual>
      <geometry>
        <mesh filename="package://aros_description/meshes/arm/link1/body.dae"/>
      </geometry>
    </visual>
    <collision>
      <geometry>
        <mesh filename="package://aros_description/meshes/arm/link1/link.dae"/>
      </geometry>
    </collision>
  </link>
  <joint name="left_joint1" type="revolute">
    <axis xyz="0 0 1"/>
    <limit effort="160.0" lower="-1.57079632679" upper="2.61799387799" velocity="0.5"/>
    <parent link="left_arm0_link"/>
    <child link="left_arm1_link"/>
    <origin rpy="0.0 0.0 0.0" xyz="0.0 0.0 0.2"/>
  </joint>
  <link name="left_arm2_link">
    <visual>
      <geometry>
        <mesh filename="package://aros_description/meshes/arm/link2/body.dae"/>
      </geometry>
    </visual>
    <collision>
      <geometry>
        <mesh filename="package://aros_description/meshes/arm/link2/link.dae"/>
      </geometry>
    </collision>
  </link>
  <joint name="left_joint2" type="revolute">
    <axis xyz="0 0 1"/>
    <limit effort="160.0" lower="-1.65806278939" upper="0.785398163397" velocity="0.5"/>
    <parent link="left_arm1_link"/>
    <child link="left_arm2_link"/>
    <origin rpy="1.57079632679 1.57079632679 0.0" xyz="0.0 0.0 0.14"/>
  </joint>
  <link name="left_arm3_link">
    <visual>
      <geometry>
        <mesh filename="package://aros_description/meshes/arm/link3/body.dae"/>
      </geometry>
    </visual>
    <collision>
      <geometry>
        <mesh filename="package://aros_description/meshes/arm/link3/link.dae"/>
      </geometry>
    </collision>
  </link>
  <joint name="left_joint3" type="revolute">
    <axis xyz="0 0 1"/>
    <limit effort="160.0" lower="-2.44346095279" upper="1.57079632679" velocity="0.5"/>
    <parent link="left_arm2_link"/>
    <child link="left_arm3_link"/>
    <origin rpy="-1.57079632679 0.0 1.57079632679" xyz="-0.195 0.0 0.0"/>
  </joint>
  <link name="left_arm4_link">
    <visual>
      <geometry>
        <mesh filename="package://aros_description/meshes/arm/link4/body.dae"/>
      </geometry>
    </visual>
    <collision>
      <geometry>
        <mesh filename="package://aros_description/meshes/arm/link4/link.dae"/>
      </geometry>
    </collision>
  </link>
  <joint name="left_joint4" type="revolute">
    <axis xyz="0 0 1"/>
    <limit effort="160.0" lower="-2.87979326579" upper="0.261799387799" velocity="0.5"/>
    <parent link="left_arm3_link"/>
    <child link="left_arm4_link"/>
    <origin rpy="1.57079632679 1.57079632679 0.0" xyz="0.0 0.0 0.2"/>
  </joint>
  <link name="left_arm5_link">
    <visual>
      <geometry>
        <mesh filename="package://aros_description/meshes/arm/link5/body.dae"/>
      </geometry>
    </visual>
    <collision>
      <geometry>
        <mesh filename="package://aros_description/meshes/arm/link5/link.dae"/>
      </geometry>
    </collision>
  </link>
  <joint name="left_joint5" type="revolute">
    <axis xyz="0 0 1"/>
    <limit effort="160.0" lower="-2.87979326579" upper="2.87979326579" velocity="0.5"/>
    <parent link="left_arm4_link"/>
    <child link="left_arm5_link"/>
    <origin rpy="-1.57079632679 0.0 1.57079632679" xyz="-0.208 0.0 0.0"/>
  </joint>
  <link name="left_arm6_link">
    <visual>
      <geometry>
        <mesh filename="package://aros_description/meshes/arm/link6/body.dae"/>
      </geometry>
    </visual>
    <collision>
      <geometry>
        <mesh filename="package://aros_description/meshes/arm/link6/link.dae"/>
      </geometry>
    </collision>
  </link>
  <joint name="left_joint6" type="revolute">
    <axis xyz="0 0 1"/>
    <limit effort="160.0" lower="-2.09439510239" upper="2.09439510239" velocity="0.5"/>
    <parent link="left_arm5_link"/>
    <child link="left_arm6_link"/>
    <origin rpy="1.57079632679 1.57079632679 0.0" xyz="0.0 0.0 0.161"/>
  </joint>
  <link name="left_arm7_link">
    <visual>
      <geometry>
        <mesh filename="package://aros_description/meshes/arm/link7/body.dae"/>
      </geometry>
    </visual>
    <collision>
      <geometry>
        <mesh filename="package://aros_description/meshes/arm/link7/link.dae"/>
      </geometry>
    </collision>
  </link>
  <joint name="left_joint7" type="revolute">
    <axis xyz="0 0 1"/>
    <limit effort="160.0" lower="-1.57079632679" upper="2.87979326579" velocity="0.5"/>
    <parent link="left_arm6_link"/>
    <child link="left_arm7_link"/>
    <origin rpy="-1.57079632679 0.0 1.57079632679" xyz="-0.053 0.0 0.0"/>
  </joint>
  <link name="left_hand_fts_link">
    <visual>
      <geometry>
        <mesh filename="package://aros_description/meshes/hand/hand_fts/body.dae"/>
      </geometry>
    </visual>
    <collision>
      <geometry>
        <mesh filename="package://aros_description/meshes/hand/hand_fts/link.dae"/>
      </geometry>
    </collision>
  </link>
  <joint name="left_arm7_to_left_hand_fts" type="fixed">
    <parent link="left_arm7_link"/>
    <child link="left_hand_fts_link"/>
    <origin rpy="-1.57079632679 -1.57079632679 0.0" xyz="0.0 0.0 0.065"/>
  </joint>
  <link name="left_hand_adapter_link">
    <visual>
      <geometry>
        <mesh filename="package://aros_description/meshes/hand/hand_adapter/body.dae"/>
      </geometry>
    </visual>
  </link>
  <joint name="left_hand_fts_to_left_hand_adapter" type="fixed">
    <parent link="left_hand_fts_link"/>
    <child link="left_hand_adapter_link"/>
    <origin rpy="0.0 0.0 0.0" xyz="0.04 0.0 0.0"/>
  </joint>
  <link name="left_hand_barrett_link">
    <visual>
      <geometry>
        <mesh filename="package://aros_description/meshes/hand/hand_barrett/body.dae"/>
      </geometry>
    </visual>
    <collision>
      <geometry>
        <mesh filename="package://aros_description/meshes/hand/hand_barrett/link.dae"/>
      </geometry>
    </collision>
  </link>
  <joint name="left_hand_adapter_to_left_hand_barrett" type="fixed">
    <parent link="left_hand_adapter_link"/>
    <child link="left_hand_barrett_link"/>
    <origin rpy="1.57079632679 0.0 1.57079632679" xyz="0.088 0.0 0.0"/>
  </joint>
  <link name="left_hand_sensor_link">
    <visual>
      <geometry>
        <mesh filename="package://aros_description/meshes/hand/hand_sensor/body.dae"/>
      </geometry>
    </visual>
    <collision>
      <geometry>
        <mesh filename="package://aros_description/meshes/hand/hand_sensor/link.dae"/>
      </geometry>
    </collision>
  </link>
  <joint name="left_hand_barrett_to_left_hand_sensor" type="fixed">
    <parent link="left_hand_barrett_link"/>
    <child link="left_hand_sensor_link"/>
    <origin rpy="0.0 0.0 0.0" xyz="0.0 0.0 0.0"/>
  </joint>
  <!-- 
	  <link name="left_hand_sensor_link">
	 <visual>
        <geometry>
              <mesh filename="package://aros_description/meshes/hand/hand_sensor/body.dae" />
        </geometry>
      </visual>		
		<collision>
		  <geometry>
			<mesh filename="package://aros_description/meshes/hand/hand_sensor/link.dae" />
		  </geometry>
		</collision>
    </link>		
  <joint name="left_endpoint" type="fixed">
    <parent link="left_hand_barrett_link"/>
    <child link="left_hand_sensor_link"/>
    <origin xyz="${hand_sensor_x} ${hand_sensor_y} ${hand_sensor_z}" rpy="${hand_sensor_roll} ${hand_sensor_pitch} ${hand_sensor_yaw}" />
  </joint>

-->
  <!-- finger 1 -->
  <link name="left_finger1_base_link">
    <visual>
      <geometry>
        <mesh filename="package://aros_description/meshes/hand/finger/base/body.dae"/>
      </geometry>
    </visual>
    <collision>
      <geometry>
        <mesh filename="package://aros_description/meshes/hand/finger/base/link.dae"/>
      </geometry>
    </collision>
  </link>
  <joint name="left_finger1_joint_base" type="revolute">
    <axis xyz="0 0 1"/>
    <limit effort="160.0" lower="0.0" upper="3.14159265359" velocity="0.5"/>
    <parent link="left_hand_sensor_link"/>
    <child link="left_finger1_base_link"/>
    <origin rpy="0.0 0.0 -1.57079632679" xyz="-0.025 0.0 -0.028"/>
  </joint>
  <link name="left_finger1_1_link">
    <visual>
      <geometry>
        <mesh filename="package://aros_description/meshes/hand/finger/link1/body.dae"/>
      </geometry>
    </visual>
    <collision>
      <geometry>
        <mesh filename="package://aros_description/meshes/hand/finger/link1/link.dae"/>
      </geometry>
    </collision>
  </link>
  <joint name="left_finger1_joint1" type="revolute">
    <axis xyz="0 0 1"/>
    <limit effort="160.0" lower="0.0" upper="2.44346095279" velocity="0.5"/>
    <parent link="left_finger1_base_link"/>
    <child link="left_finger1_1_link"/>
    <origin rpy="0.0 1.57079632679 1.57079632679" xyz="-0.05 0.0 0.036"/>
  </joint>
  <link name="left_finger1_2_link">
    <visual>
      <geometry>
        <mesh filename="package://aros_description/meshes/hand/finger/link2/body.dae"/>
      </geometry>
    </visual>
    <collision>
      <geometry>
        <mesh filename="package://aros_description/meshes/hand/finger/link2/link.dae"/>
      </geometry>
    </collision>
  </link>
  <joint name="left_finger1_joint2" type="revolute">
    <axis xyz="0 0 1"/>
    <limit effort="160.0" lower="0.0" upper="0.785398163397" velocity="0.5"/>
    <parent link="left_finger1_1_link"/>
    <child link="left_finger1_2_link"/>
    <origin rpy="0.0 0.0 0.0" xyz="-0.005 0.07 0.0"/>
  </joint>
  <!--	
	<link name="${prefix}_finger1_tip_link">
	 <visual>
        <geometry>
              <mesh filename="package://aros_description/meshes/hand/finger/tip/body.dae" />
        </geometry>
      </visual>		
	</link>
	
  <joint name="${prefix}_finger1_joint_tip" type="fixed">
    <parent link="${prefix}_finger1_2_link"/>
    <child link="${prefix}_finger1_tip_link"/>
    <origin xyz="${finger_tip_x} ${finger_tip_y} ${finger_tip_z}" rpy="${finger_tip_roll} ${finger_tip_pitch} ${finger_tip_yaw}"/>
  </joint>
-->
  <!-- finger 2 -->
  <link name="left_finger2_base_link">
    <visual>
      <geometry>
        <mesh filename="package://aros_description/meshes/hand/finger/base/body.dae"/>
      </geometry>
    </visual>
    <collision>
      <geometry>
        <mesh filename="package://aros_description/meshes/hand/finger/base/link.dae"/>
      </geometry>
    </collision>
  </link>
  <joint name="left_finger2_joint_base" type="revolute">
    <axis xyz="0 0 1"/>
    <limit effort="160.0" lower="-3.14159265359" upper="-0.0" velocity="0.5"/>
    <parent link="left_hand_sensor_link"/>
    <child link="left_finger2_base_link"/>
    <origin rpy="0.0 0.0 -1.57079632679" xyz="0.025 0.0 -0.028"/>
  </joint>
  <link name="left_finger2_1_link">
    <visual>
      <geometry>
        <mesh filename="package://aros_description/meshes/hand/finger/link1/body.dae"/>
      </geometry>
    </visual>
    <collision>
      <geometry>
        <mesh filename="package://aros_description/meshes/hand/finger/link1/link.dae"/>
      </geometry>
    </collision>
  </link>
  <joint name="left_finger2_joint1" type="revolute">
    <axis xyz="0 0 1"/>
    <limit effort="160.0" lower="0.0" upper="2.44346095279" velocity="0.5"/>
    <parent link="left_finger2_base_link"/>
    <child link="left_finger2_1_link"/>
    <origin rpy="0.0 1.57079632679 1.57079632679" xyz="-0.05 0.0 0.036"/>
  </joint>
  <link name="left_finger2_2_link">
    <visual>
      <geometry>
        <mesh filename="package://aros_description/meshes/hand/finger/link2/body.dae"/>
      </geometry>
    </visual>
    <collision>
      <geometry>
        <mesh filename="package://aros_description/meshes/hand/finger/link2/link.dae"/>
      </geometry>
    </collision>
  </link>
  <joint name="left_finger2_joint2" type="revolute">
    <axis xyz="0 0 1"/>
    <limit effort="160.0" lower="0.0" upper="0.785398163397" velocity="0.5"/>
    <parent link="left_finger2_1_link"/>
    <child link="left_finger2_2_link"/>
    <origin rpy="0.0 0.0 0.0" xyz="-0.005 0.07 0.0"/>
  </joint>
  <!--
	<link name="${prefix}_finger2_tip_link">
	 <visual>
        <geometry>
              <mesh filename="package://aros_description/meshes/hand/finger/tip/body.dae" />
        </geometry>
      </visual>		
	</link>
	
  <joint name="${prefix}_finger2_joint_tip" type="fixed">
    <parent link="${prefix}_finger2_2_link"/>
    <child link="${prefix}_finger2_tip_link"/>
    <origin xyz="${finger_tip_x} ${finger_tip_y} ${finger_tip_z}" rpy="${finger_tip_roll} ${finger_tip_pitch} ${finger_tip_yaw}"/>
  </joint>
-->
  <!-- finger 3 -->
  <link name="left_finger3_1_link">
    <visual>
      <geometry>
        <mesh filename="package://aros_description/meshes/hand/finger/link1/body.dae"/>
      </geometry>
    </visual>
    <collision>
      <geometry>
        <mesh filename="package://aros_description/meshes/hand/finger/link1/link.dae"/>
      </geometry>
    </collision>
  </link>
  <joint name="left_finger3_joint1" type="revolute">
    <axis xyz="0 0 1"/>
    <limit effort="160.0" lower="0.0" upper="2.44346095279" velocity="0.5"/>
    <parent link="left_hand_sensor_link"/>
    <child link="left_finger3_1_link"/>
    <origin rpy="-1.57079632679 1.57079632679 1.57079632679" xyz="0.0 -0.05 0.008"/>
  </joint>
  <link name="left_finger3_2_link">
    <visual>
      <geometry>
        <mesh filename="package://aros_description/meshes/hand/finger/link2/body.dae"/>
      </geometry>
    </visual>
    <collision>
      <geometry>
        <mesh filename="package://aros_description/meshes/hand/finger/link2/link.dae"/>
      </geometry>
    </collision>
  </link>
  <joint name="left_finger3_joint2" type="revolute">
    <axis xyz="0 0 1"/>
    <limit effort="160.0" lower="0.0" upper="0.785398163397" velocity="0.5"/>
    <parent link="left_finger3_1_link"/>
    <child link="left_finger3_2_link"/>
    <origin rpy="0.0 0.0 0.0" xyz="-0.005 0.07 0.0"/>
  </joint>
  <!--	
	<link name="${prefix}_finger3_tip_link">
	 <visual>
        <geometry>
              <mesh filename="package://aros_description/meshes/hand/finger/tip/body.dae" />
        </geometry>
      </visual>		
	</link>
	
  <joint name="${prefix}_finger3_joint_tip" type="fixed">
    <parent link="${prefix}_finger3_2_link"/>
    <child link="${prefix}_finger3_tip_link"/>
    <origin xyz="${finger_tip_x} ${finger_tip_y} ${finger_tip_z}" rpy="${finger_tip_roll} ${finger_tip_pitch} ${finger_tip_yaw}"/>
  </joint>
-->
</robot>
